Workbook

Sheet fact_bookingswork H2 (2)
A1: booking_id | B1: booking_date | C1: check_in_date | D1: channel_id | E1: rate_code_id | F1: gross_room_revenue | G1: commission_amount | H1: net_room_revenue | I1: status | J1: net_margin | K1: channel_type | L1: channel_name | M1: Cancelled Flag | N1: Checked-Out Flag | O1: Net_revenue | P1: Gross Revenue | Q1: total_booking
A2: BK10001 | B2: 2024-02-27 | C2: 2024-02-27 | D2: CH_02 | E2: RT_PROMO | F2: 22632.18 | G2: 4073.79 | H2: 18558.39 | I2: Checked-Out | J2: 1.219512 | K2: =_xlfn.XLOOKUP(D2, dim_channels!A:A, dim_channels!C:C, "Not Found") -> OTA | L2: =_xlfn.XLOOKUP(D2, dim_channels!A:A, dim_channels!B:B, "Not Found") -> Expedia | M2: =IF(I2="Cancelled",1,0) -> 0 | N2: =IF(TRIM(UPPER(I2))="CHECKED-OUT",1,0) -> 1 | O2: =IF(TRIM(UPPER(I2))="CHECKED-OUT",H2,0) -> 18558.39 | P2: =IF(TRIM(UPPER(I2))="CHECKED-OUT",F2,0) -> 22632.18
A3: BK10002 | B3: 2024-04-24 | C3: 2024-04-28 | D3: CH_01 | E3: RT_BAR | F3: 3311.74 | G3: 496.76 | H3: 2814.98 | I3: Checked-Out | J3: 1.1764702 | K3: =_xlfn.XLOOKUP(D3, dim_channels!A:A, dim_channels!C:C, "Not Found") -> OTA | L3: =_xlfn.XLOOKUP(D3, dim_channels!A:A, dim_channels!B:B, "Not Found") -> Booking.com | M3: =IF(I3="Cancelled",1,0) -> 0 | N3: =IF(TRIM(UPPER(I3))="CHECKED-OUT",1,0) -> 1 | O3: =IF(TRIM(UPPER(I3))="CHECKED-OUT",H3,0) -> 2814.98 | P3: =IF(TRIM(UPPER(I3))="CHECKED-OUT",F3,0) -> 3311.74
A4: BK10003 | B4: 2024-10-06 | C4: 2024-10-08 | D4: CH_01 | E4: RT_PROMO | F4: 17985.32 | G4: 2697.8 | H4: 15287.52 | I4: Checked-Out | J4: 1.1764707 | K4: =_xlfn.XLOOKUP(D4, dim_channels!A:A, dim_channels!C:C, "Not Found") -> OTA | L4: =_xlfn.XLOOKUP(D4, dim_channels!A:A, dim_channels!B:B, "Not Found") -> Booking.com | M4: =IF(I4="Cancelled",1,0) -> 0 | N4: =IF(TRIM(UPPER(I4))="CHECKED-OUT",1,0) -> 1 | O4: =IF(TRIM(UPPER(I4))="CHECKED-OUT",H4,0) -> 15287.52 | P4: =IF(TRIM(UPPER(I4))="CHECKED-OUT",F4,0) -> 17985.32
A5: BK10004 | B5: 2024-01-16 | C5: 2024-01-18 | D5: CH_01 | E5: RT_BAR | F5: 21405.01 | G5: 3210.75 | H5: 18194.26 | I5: Cancelled | J5: 1.1764705 | K5: =_xlfn.XLOOKUP(D5, dim_channels!A:A, dim_channels!C:C, "Not Found") -> OTA | L5: =_xlfn.XLOOKUP(D5, dim_channels!A:A, dim_channels!B:B, "Not Found") -> Booking.com | M5: =IF(I5="Cancelled",1,0) -> 1 | N5: =IF(TRIM(UPPER(I5))="CHECKED-OUT",1,0) -> 0 | O5: =IF(TRIM(UPPER(I5))="CHECKED-OUT",H5,0) -> 0 | P5: =IF(TRIM(UPPER(I5))="CHECKED-OUT",F5,0) -> 0
A6: BK10005 | B6: 2024-10-14 | C6: 2024-10-20 | D6: CH_06 | E6: RT_CORP | F6: 3442.3 | G6: 172.12 | H6: 3270.18 | I6: Checked-Out | J6: 1.0526332 | K6: =_xlfn.XLOOKUP(D6, dim_channels!A:A, dim_channels!C:C, "Not Found") -> Corporate | L6: =_xlfn.XLOOKUP(D6, dim_channels!A:A, dim_channels!B:B, "Not Found") -> Corporate Direct | M6: =IF(I6="Cancelled",1,0) -> 0 | N6: =IF(TRIM(UPPER(I6))="CHECKED-OUT",1,0) -> 1 | O6: =IF(TRIM(UPPER(I6))="CHECKED-OUT",H6,0) -> 3270.18 | P6: =IF(TRIM(UPPER(I6))="CHECKED-OUT",F6,0) -> 3442.3
A7: BK10006 | B7: 2024-10-06 | C7: 2024-10-19 | D7: CH_02 | E7: RT_PROMO | F7: 7647.31 | G7: 1376.52 | H7: 6270.79 | I7: Cancelled | J7: 1.219513 | K7: =_xlfn.XLOOKUP(D7, dim_channels!A:A, dim_channels!C:C, "Not Found") -> OTA | L7: =_xlfn.XLOOKUP(D7, dim_channels!A:A, dim_channels!B:B, "Not Found") -> Expedia | M7: =IF(I7="Cancelled",1,0) -> 1 | N7: =IF(TRIM(UPPER(I7))="CHECKED-OUT",1,0) -> 0 | O7: =IF(TRIM(UPPER(I7))="CHECKED-OUT",H7,0) -> 0 | P7: =IF(TRIM(UPPER(I7))="CHECKED-OUT",F7,0) -> 0
A8: BK10007 | B8: 2024-01-04 | C8: 2024-01-28 | D8: CH_03 | E8: RT_BAR | F8: 4567.99 | G8: 548.16 | H8: 4019.83 | I8: Checked-Out | J8: 1.136364 | K8: =_xlfn.XLOOKUP(D8, dim_channels!A:A, dim_channels!C:C, "Not Found") -> OTA | L8: =_xlfn.XLOOKUP(D8, dim_channels!A:A, dim_channels!B:B, "Not Found") -> Agoda | M8: =IF(I8="Cancelled",1,0) -> 0 | N8: =IF(TRIM(UPPER(I8))="CHECKED-OUT",1,0) -> 1 | O8: =IF(TRIM(UPPER(I8))="CHECKED-OUT",H8,0) -> 4019.83 | P8: =IF(TRIM(UPPER(I8))="CHECKED-OUT",F8,0) -> 4567.99
A9: BK10008 | B9: 2024-08-04 | C9: 2024-08-14 | D9: CH_02 | E9: RT_PROMO | F9: 6226.26 | G9: 1120.73 | H9: 5105.53 | I9: Confirmed | J9: 1.219513 | K9: =_xlfn.XLOOKUP(D9, dim_channels!A:A, dim_channels!C:C, "Not Found") -> OTA | L9: =_xlfn.XLOOKUP(D9, dim_channels!A:A, dim_channels!B:B, "Not Found") -> Expedia | M9: =IF(I9="Cancelled",1,0) -> 0 | N9: =IF(TRIM(UPPER(I9))="CHECKED-OUT",1,0) -> 0 | O9: =IF(TRIM(UPPER(I9))="CHECKED-OUT",H9,0) -> 0 | P9: =IF(TRIM(UPPER(I9))="CHECKED-OUT",F9,0) -> 0
A10: BK10009 | B10: 2024-06-21 | C10: 2024-06-24 | D10: CH_03 | E10: RT_NET | F10: 10484.28 | G10: 0 | H10: 10484.28 | I10: Cancelled | J10: 1 | K10: =_xlfn.XLOOKUP(D10, dim_channels!A:A, dim_channels!C:C, "Not Found") -> OTA | L10: =_xlfn.XLOOKUP(D10, dim_channels!A:A, dim_channels!B:B, "Not Found") -> Agoda | M10: =IF(I10="Cancelled",1,0) -> 1 | N10: =IF(TRIM(UPPER(I10))="CHECKED-OUT",1,0) -> 0 | O10: =IF(TRIM(UPPER(I10))="CHECKED-OUT",H10,0) -> 0 | P10: =IF(TRIM(UPPER(I10))="CHECKED-OUT",F10,0) -> 0
A11: BK10010 | B11: 2024-07-02 | C11: 2024-07-29 | D11: CH_04 | E11: RT_BAR | F11: 2652.9 | G11: 0 | H11: 2652.9 | I11: Checked-Out | J11: 1 | K11: =_xlfn.XLOOKUP(D11, dim_channels!A:A, dim_channels!C:C, "Not Found") -> Direct | L11: =_xlfn.XLOOKUP(D11, dim_channels!A:A, dim_channels!B:B, "Not Found") -> Direct Website | M11: =IF(I11="Cancelled",1,0) -> 0 | N11: =IF(TRIM(UPPER(I11))="CHECKED-OUT",1,0) -> 1 | O11: =IF(TRIM(UPPER(I11))="CHECKED-OUT",H11,0) -> 2652.9 | P11: =IF(TRIM(UPPER(I11))="CHECKED-OUT",F11,0) -> 2652.9
A12: BK10011 | B12: 2024-01-23 | C12: 2024-02-15 | D12: CH_04 | E12: RT_PROMO | F12: 2969.35 | G12: 0 | H12: 2969.35 | I12: Checked-Out | J12: 1 | K12: =_xlfn.XLOOKUP(D12, dim_channels!A:A, dim_channels!C:C, "Not Found") -> Direct | L12: =_xlfn.XLOOKUP(D12, dim_channels!A:A, dim_channels!B:B, "Not Found") -> Direct Website | M12: =IF(I12="Cancelled",1,0) -> 0 | N12: =IF(TRIM(UPPER(I12))="CHECKED-OUT",1,0) -> 1 | O12: =IF(TRIM(UPPER(I12))="CHECKED-OUT",H12,0) -> 2969.35 | P12: =IF(TRIM(UPPER(I12))="CHECKED-OUT",F12,0) -> 2969.35
A13: BK10012 | B13: 2024-07-12 | C13: 2024-07-14 | D13: CH_04 | E13: RT_BAR | F13: 6175.98 | G13: 0 | H13: 6175.98 | I13: Checked-Out | J13: 1 | K13: =_xlfn.XLOOKUP(D13, dim_channels!A:A, dim_channels!C:C, "Not Found") -> Direct | L13: =_xlfn.XLOOKUP(D13, dim_channels!A:A, dim_channels!B:B, "Not Found") -> Direct Website | M13: =IF(I13="Cancelled",1,0) -> 0 | N13: =IF(TRIM(UPPER(I13))="CHECKED-OUT",1,0) -> 1 | O13: =IF(TRIM(UPPER(I13))="CHECKED-OUT",H13,0) -> 6175.98 | P13: =IF(TRIM(UPPER(I13))="CHECKED-OUT",F13,0) -> 6175.98
... A5001: BK15000 | B5001: 2024-03-27 | C5001: 2024-04-23 | D5001: CH_02 | E5001: RT_BAR | F5001: 6607.36 | G5001: 1189.32 | H5001: 5418.04 | I5001: Checked-Out | J5001: 1.2195111 | K5001: =_xlfn.XLOOKUP(D5001, dim_channels!A:A, dim_channels!C:C, "Not Found") -> OTA | L5001: =_xlfn.XLOOKUP(D5001, dim_channels!A:A, dim_channels!B:B, "Not Found") -> Expedia | M5001: =IF(I5001="Cancelled",1,0) -> 0 | N5001: =IF(TRIM(UPPER(I5001))="CHECKED-OUT",1,0) -> 1 | O5001: =IF(TRIM(UPPER(I5001))="CHECKED-OUT",H5001,0) -> 5418.04 | P5001: =IF(TRIM(UPPER(I5001))="CHECKED-OUT",F5001,0) -> 6607.36

Sheet H2fact_bookingswork 
A1: booking_id | B1: booking_date | C1: check_in_date | D1: channel_id | E1: rate_code_id | F1: gross_room_revenue | G1: commission_amount | H1: net_room_revenue | I1: status | J1: net_margin | K1: channel_type | L1: channel_name
A2: BK10001 | B2: 2024-02-27 | C2: 2024-02-27 | D2: CH_02 | E2: RT_PROMO | F2: 22632.18 | G2: 4073.79 | H2: 18558.39 | I2: Checked-Out | J2: 1.219512 | K2: =_xlfn.XLOOKUP(D2, dim_channels!A:A, dim_channels!C:C, "Not Found") -> OTA | L2: =_xlfn.XLOOKUP(D2, dim_channels!A:A, dim_channels!B:B, "Not Found") -> Expedia
A3: BK10002 | B3: 2024-04-24 | C3: 2024-04-28 | D3: CH_01 | E3: RT_BAR | F3: 3311.74 | G3: 496.76 | H3: 2814.98 | I3: Checked-Out | J3: 1.1764702 | K3: =_xlfn.XLOOKUP(D3, dim_channels!A:A, dim_channels!C:C, "Not Found") -> OTA | L3: =_xlfn.XLOOKUP(D3, dim_channels!A:A, dim_channels!B:B, "Not Found") -> Booking.com
A4: BK10003 | B4: 2024-10-06 | C4: 2024-10-08 | D4: CH_01 | E4: RT_PROMO | F4: 17985.32 | G4: 2697.8 | H4: 15287.52 | I4: Checked-Out | J4: 1.1764707 | K4: =_xlfn.XLOOKUP(D4, dim_channels!A:A, dim_channels!C:C, "Not Found") -> OTA | L4: =_xlfn.XLOOKUP(D4, dim_channels!A:A, dim_channels!B:B, "Not Found") -> Booking.com
A5: BK10004 | B5: 2024-01-16 | C5: 2024-01-18 | D5: CH_01 | E5: RT_BAR | F5: 21405.01 | G5: 3210.75 | H5: 18194.26 | I5: Cancelled | J5: 1.1764705 | K5: =_xlfn.XLOOKUP(D5, dim_channels!A:A, dim_channels!C:C, "Not Found") -> OTA | L5: =_xlfn.XLOOKUP(D5, dim_channels!A:A, dim_channels!B:B, "Not Found") -> Booking.com
A6: BK10005 | B6: 2024-10-14 | C6: 2024-10-20 | D6: CH_06 | E6: RT_CORP | F6: 3442.3 | G6: 172.12 | H6: 3270.18 | I6: Checked-Out | J6: 1.0526332 | K6: =_xlfn.XLOOKUP(D6, dim_channels!A:A, dim_channels!C:C, "Not Found") -> Corporate | L6: =_xlfn.XLOOKUP(D6, dim_channels!A:A, dim_channels!B:B, "Not Found") -> Corporate Direct
A7: BK10006 | B7: 2024-10-06 | C7: 2024-10-19 | D7: CH_02 | E7: RT_PROMO | F7: 7647.31 | G7: 1376.52 | H7: 6270.79 | I7: Cancelled | J7: 1.219513 | K7: =_xlfn.XLOOKUP(D7, dim_channels!A:A, dim_channels!C:C, "Not Found") -> OTA | L7: =_xlfn.XLOOKUP(D7, dim_channels!A:A, dim_channels!B:B, "Not Found") -> Expedia
A8: BK10007 | B8: 2024-01-04 | C8: 2024-01-28 | D8: CH_03 | E8: RT_BAR | F8: 4567.99 | G8: 548.16 | H8: 4019.83 | I8: Checked-Out | J8: 1.136364 | K8: =_xlfn.XLOOKUP(D8, dim_channels!A:A, dim_channels!C:C, "Not Found") -> OTA | L8: =_xlfn.XLOOKUP(D8, dim_channels!A:A, dim_channels!B:B, "Not Found") -> Agoda
A9: BK10008 | B9: 2024-08-04 | C9: 2024-08-14 | D9: CH_02 | E9: RT_PROMO | F9: 6226.26 | G9: 1120.73 | H9: 5105.53 | I9: Confirmed | J9: 1.219513 | K9: =_xlfn.XLOOKUP(D9, dim_channels!A:A, dim_channels!C:C, "Not Found") -> OTA | L9: =_xlfn.XLOOKUP(D9, dim_channels!A:A, dim_channels!B:B, "Not Found") -> Expedia
A10: BK10009 | B10: 2024-06-21 | C10: 2024-06-24 | D10: CH_03 | E10: RT_NET | F10: 10484.28 | G10: 0 | H10: 10484.28 | I10: Cancelled | J10: 1 | K10: =_xlfn.XLOOKUP(D10, dim_channels!A:A, dim_channels!C:C, "Not Found") -> OTA | L10: =_xlfn.XLOOKUP(D10, dim_channels!A:A, dim_channels!B:B, "Not Found") -> Agoda
A11: BK10010 | B11: 2024-07-02 | C11: 2024-07-29 | D11: CH_04 | E11: RT_BAR | F11: 2652.9 | G11: 0 | H11: 2652.9 | I11: Checked-Out | J11: 1 | K11: =_xlfn.XLOOKUP(D11, dim_channels!A:A, dim_channels!C:C, "Not Found") -> Direct | L11: =_xlfn.XLOOKUP(D11, dim_channels!A:A, dim_channels!B:B, "Not Found") -> Direct Website
A12: BK10011 | B12: 2024-01-23 | C12: 2024-02-15 | D12: CH_04 | E12: RT_PROMO | F12: 2969.35 | G12: 0 | H12: 2969.35 | I12: Checked-Out | J12: 1 | K12: =_xlfn.XLOOKUP(D12, dim_channels!A:A, dim_channels!C:C, "Not Found") -> Direct | L12: =_xlfn.XLOOKUP(D12, dim_channels!A:A, dim_channels!B:B, "Not Found") -> Direct Website
A13: BK10012 | B13: 2024-07-12 | C13: 2024-07-14 | D13: CH_04 | E13: RT_BAR | F13: 6175.98 | G13: 0 | H13: 6175.98 | I13: Checked-Out | J13: 1 | K13: =_xlfn.XLOOKUP(D13, dim_channels!A:A, dim_channels!C:C, "Not Found") -> Direct | L13: =_xlfn.XLOOKUP(D13, dim_channels!A:A, dim_channels!B:B, "Not Found") -> Direct Website
... A5001: BK15000 | B5001: 2024-03-27 | C5001: 2024-04-23 | D5001: CH_02 | E5001: RT_BAR | F5001: 6607.36 | G5001: 1189.32 | H5001: 5418.04 | I5001: Checked-Out | J5001: 1.2195111 | K5001: =_xlfn.XLOOKUP(D5001, dim_channels!A:A, dim_channels!C:C, "Not Found") -> OTA | L5001: =_xlfn.XLOOKUP(D5001, dim_channels!A:A, dim_channels!B:B, "Not Found") -> Expedia

Sheet README
A1: HOTEL CHANNEL PROFITABILITY DATASET | B1: Unnamed: 1
A2: Generated for Data Analytics Training
A4: TABLE | B4: ROWS
A5: fact_bookings | B5: 5000
A6: dim_channels | B6: 8
A7: dim_rate_codes | B7: 7
A8: fact_marketing_spend | B8: 1256
A10: OBJECTIVE | B10: Analyze channel profitability: gross revenue, commission leakage, net yield
A11: DATE RANGE | B11: 2024-01-01 to 2024-12-31
A12: CURRENCY | B12: THB (Thai Baht)

Sheet fact_bookingswork
A1: booking_id | B1: booking_date | C1: check_in_date | D1: channel_id | E1: rate_code_id | F1: gross_room_revenue | G1: commission_amount | H1: net_room_revenue | I1: status | J1: net_margin | K1: channel_type | L1: channel_name
A2: BK10001 | B2: 2024-02-27 | C2: 2024-02-27 | D2: CH_02 | E2: RT_PROMO | F2: 22632.18 | G2: 4073.79 | H2: 18558.39 | I2: Checked-Out | J2: 1.219512 | K2: =_xlfn.XLOOKUP(D2, dim_channels!A:A, dim_channels!C:C, "Not Found") -> OTA | L2: =_xlfn.XLOOKUP(D2, dim_channels!A:A, dim_channels!B:B, "Not Found") -> Expedia
A3: BK10002 | B3: 2024-04-24 | C3: 2024-04-28 | D3: CH_01 | E3: RT_BAR | F3: 3311.74 | G3: 496.76 | H3: 2814.98 | I3: Checked-Out | J3: 1.1764702 | K3: =_xlfn.XLOOKUP(D3, dim_channels!A:A, dim_channels!C:C, "Not Found") -> OTA | L3: =_xlfn.XLOOKUP(D3, dim_channels!A:A, dim_channels!B:B, "Not Found") -> Booking.com
A4: BK10003 | B4: 2024-10-06 | C4: 2024-10-08 | D4: CH_01 | E4: RT_PROMO | F4: 17985.32 | G4: 2697.8 | H4: 15287.52 | I4: Checked-Out | J4: 1.1764707 | K4: =_xlfn.XLOOKUP(D4, dim_channels!A:A, dim_channels!C:C, "Not Found") -> OTA | L4: =_xlfn.XLOOKUP(D4, dim_channels!A:A, dim_channels!B:B, "Not Found") -> Booking.com
A5: BK10004 | B5: 2024-01-16 | C5: 2024-01-18 | D5: CH_01 | E5: RT_BAR | F5: 21405.01 | G5: 3210.75 | H5: 18194.26 | I5: Cancelled | J5: 1.1764705 | K5: =_xlfn.XLOOKUP(D5, dim_channels!A:A, dim_channels!C:C, "Not Found") -> OTA | L5: =_xlfn.XLOOKUP(D5, dim_channels!A:A, dim_channels!B:B, "Not Found") -> Booking.com
A6: BK10005 | B6: 2024-10-14 | C6: 2024-10-20 | D6: CH_06 | E6: RT_CORP | F6: 3442.3 | G6: 172.12 | H6: 3270.18 | I6: Checked-Out | J6: 1.0526332 | K6: =_xlfn.XLOOKUP(D6, dim_channels!A:A, dim_channels!C:C, "Not Found") -> Corporate | L6: =_xlfn.XLOOKUP(D6, dim_channels!A:A, dim_channels!B:B, "Not Found") -> Corporate Direct
A7: BK10006 | B7: 2024-10-06 | C7: 2024-10-19 | D7: CH_02 | E7: RT_PROMO | F7: 7647.31 | G7: 1376.52 | H7: 6270.79 | I7: Cancelled | J7: 1.219513 | K7: =_xlfn.XLOOKUP(D7, dim_channels!A:A, dim_channels!C:C, "Not Found") -> OTA | L7: =_xlfn.XLOOKUP(D7, dim_channels!A:A, dim_channels!B:B, "Not Found") -> Expedia
A8: BK10007 | B8: 2024-01-04 | C8: 2024-01-28 | D8: CH_03 | E8: RT_BAR | F8: 4567.99 | G8: 548.16 | H8: 4019.83 | I8: Checked-Out | J8: 1.136364 | K8: =_xlfn.XLOOKUP(D8, dim_channels!A:A, dim_channels!C:C, "Not Found") -> OTA | L8: =_xlfn.XLOOKUP(D8, dim_channels!A:A, dim_channels!B:B, "Not Found") -> Agoda
A9: BK10008 | B9: 2024-08-04 | C9: 2024-08-14 | D9: CH_02 | E9: RT_PROMO | F9: 6226.26 | G9: 1120.73 | H9: 5105.53 | I9: Confirmed | J9: 1.219513 | K9: =_xlfn.XLOOKUP(D9, dim_channels!A:A, dim_channels!C:C, "Not Found") -> OTA | L9: =_xlfn.XLOOKUP(D9, dim_channels!A:A, dim_channels!B:B, "Not Found") -> Expedia
A10: BK10009 | B10: 2024-06-21 | C10: 2024-06-24 | D10: CH_03 | E10: RT_NET | F10: 10484.28 | G10: 0 | H10: 10484.28 | I10: Cancelled | J10: 1 | K10: =_xlfn.XLOOKUP(D10, dim_channels!A:A, dim_channels!C:C, "Not Found") -> OTA | L10: =_xlfn.XLOOKUP(D10, dim_channels!A:A, dim_channels!B:B, "Not Found") -> Agoda
A11: BK10010 | B11: 2024-07-02 | C11: 2024-07-29 | D11: CH_04 | E11: RT_BAR | F11: 2652.9 | G11: 0 | H11: 2652.9 | I11: Checked-Out | J11: 1 | K11: =_xlfn.XLOOKUP(D11, dim_channels!A:A, dim_channels!C:C, "Not Found") -> Direct | L11: =_xlfn.XLOOKUP(D11, dim_channels!A:A, dim_channels!B:B, "Not Found") -> Direct Website
A12: BK10011 | B12: 2024-01-23 | C12: 2024-02-15 | D12: CH_04 | E12: RT_PROMO | F12: 2969.35 | G12: 0 | H12: 2969.35 | I12: Checked-Out | J12: 1 | K12: =_xlfn.XLOOKUP(D12, dim_channels!A:A, dim_channels!C:C, "Not Found") -> Direct | L12: =_xlfn.XLOOKUP(D12, dim_channels!A:A, dim_channels!B:B, "Not Found") -> Direct Website
A13: BK10012 | B13: 2024-07-12 | C13: 2024-07-14 | D13: CH_04 | E13: RT_BAR | F13: 6175.98 | G13: 0 | H13: 6175.98 | I13: Checked-Out | J13: 1 | K13: =_xlfn.XLOOKUP(D13, dim_channels!A:A, dim_channels!C:C, "Not Found") -> Direct | L13: =_xlfn.XLOOKUP(D13, dim_channels!A:A, dim_channels!B:B, "Not Found") -> Direct Website
... A5001: BK15000 | B5001: 2024-03-27 | C5001: 2024-04-23 | D5001: CH_02 | E5001: RT_BAR | F5001: 6607.36 | G5001: 1189.32 | H5001: 5418.04 | I5001: Checked-Out | J5001: 1.2195111 | K5001: =_xlfn.XLOOKUP(D5001, dim_channels!A:A, dim_channels!C:C, "Not Found") -> OTA | L5001: =_xlfn.XLOOKUP(D5001, dim_channels!A:A, dim_channels!B:B, "Not Found") -> Expedia

Sheet fact_bookings
A1: booking_id | B1: booking_date | C1: check_in_date | D1: channel_id | E1: rate_code_id | F1: gross_room_revenue | G1: commission_amount | H1: net_room_revenue | I1: status
A2: BK10001 | B2: 2024-02-27 | C2: 2024-02-27 | D2: CH_02 | E2: RT_PROMO | F2: 22632.18 | G2: 4073.79 | H2: 18558.39 | I2: Checked-Out
A3: BK10002 | B3: 2024-04-24 | C3: 2024-04-28 | D3: CH_01 | E3: RT_BAR | F3: 3311.74 | G3: 496.76 | H3: 2814.98 | I3: Checked-Out
A4: BK10003 | B4: 2024-10-06 | C4: 2024-10-08 | D4: CH_01 | E4: RT_PROMO | F4: 17985.32 | G4: 2697.8 | H4: 15287.52 | I4: Checked-Out
A5: BK10004 | B5: 2024-01-16 | C5: 2024-01-18 | D5: CH_01 | E5: RT_BAR | F5: 21405.01 | G5: 3210.75 | H5: 18194.26 | I5: Cancelled
A6: BK10005 | B6: 2024-10-14 | C6: 2024-10-20 | D6: CH_06 | E6: RT_CORP | F6: 3442.3 | G6: 172.12 | H6: 3270.18 | I6: Checked-Out
A7: BK10006 | B7: 2024-10-06 | C7: 2024-10-19 | D7: CH_02 | E7: RT_PROMO | F7: 7647.31 | G7: 1376.52 | H7: 6270.79 | I7: Cancelled
A8: BK10007 | B8: 2024-01-04 | C8: 2024-01-28 | D8: CH_03 | E8: RT_BAR | F8: 4567.99 | G8: 548.16 | H8: 4019.83 | I8: Checked-Out
A9: BK10008 | B9: 2024-08-04 | C9: 2024-08-14 | D9: CH_02 | E9: RT_PROMO | F9: 6226.26 | G9: 1120.73 | H9: 5105.53 | I9: Confirmed
A10: BK10009 | B10: 2024-06-21 | C10: 2024-06-24 | D10: CH_03 | E10: RT_NET | F10: 10484.28 | G10: 0 | H10: 10484.28 | I10: Cancelled
A11: BK10010 | B11: 2024-07-02 | C11: 2024-07-29 | D11: CH_04 | E11: RT_BAR | F11: 2652.9 | G11: 0 | H11: 2652.9 | I11: Checked-Out
A12: BK10011 | B12: 2024-01-23 | C12: 2024-02-15 | D12: CH_04 | E12: RT_PROMO | F12: 2969.35 | G12: 0 | H12: 2969.35 | I12: Checked-Out
A13: BK10012 | B13: 2024-07-12 | C13: 2024-07-14 | D13: CH_04 | E13: RT_BAR | F13: 6175.98 | G13: 0 | H13: 6175.98 | I13: Checked-Out
... A4971: BK14970 | B4971: 2024-01-25 | C4971: 2024-02-24 | D4971: CH_03 | E4971: RT_NET | F4971: 9304.17 | G4971: 0 | H4971: 9304.17 | I4971: Cancelled
A4972: BK14971 | B4972: 2024-01-29 | C4972: 45339 | D4972: CH_04 | E4972: RT_PKG | F4972: 2831.22 | G4972: 0 | H4972: 2831.22 | I4972: Checked-Out
A4973: BK14972 | B4973: 2024-05-30 | C4973: 2024-06-19 | D4973: CH_01 | E4973: RT_BAR | F4973: 2210.29 | G4973: 331.54 | H4973: 1878.75 | I4973: Checked-Out
A4974: BK14973 | B4974: 2024-06-13 | C4974: 2024-06-14 | D4974: CH_01 | E4974: RT_PROMO | F4974: 18686.46 | G4974: 2802.97 | H4974: 15883.49 | I4974: Checked-Out
A4975: BK14974 | B4975: 2024-11-18 | C4975: 2024-12-04 | D4975: CH_01 | E4975: RT_BAR | F4975: 11643.07 | G4975: 1746.46 | H4975: 9896.61 | I4975: Cancelled
A4976: BK14975 | B4976: 2024-11-24 | C4976: 2024-12-07 | D4976: CH_03 | E4976: RT_BAR | F4976: 14327.16 | G4976: 1719.26 | H4976: 12607.9 | I4976: Checked-Out
A4977: BK14976 | B4977: 2024-07-07 | C4977: 2024-07-14 | D4977: CH_01 | E4977: RT_BAR | F4977: 12176.91 | G4977: 1826.54 | H4977: 10350.37 | I4977: Checked-Out
A4978: BK14977 | B4978: 2024-01-09 | C4978: 2024-02-06 | D4978: CH_08 | E4978: RT_CORP | F4978: 8040.76 | G4978: 1608.15 | H4978: 6432.61 | I4978: Checked-Out
A4979: BK14978 | B4979: 2024-11-02 | C4979: 2024-11-11 | D4979: CH_03 | E4979: RT_BAR | F4979: 12126.61 | G4979: 1455.19 | H4979: 10671.42 | I4979: Checked-Out
A4980: BK14979 | B4980: 2024-12-31 | C4980: 2025-01-30 | D4980: CH_07 | E4980: RT_PKG | F4980: 10976.01 | G4980: 1097.6 | H4980: 9878.41 | I4980: Checked-Out
A4981: BK14980 | B4981: 2024-07-25 | C4981: 2024-08-18 | D4981: CH_01 | E4981: RT_BAR | F4981: 5923.64 | G4981: 888.55 | H4981: 5035.09 | I4981: Checked-Out
A4982: BK14981 | B4982: 2024-03-07 | C4982: 2024-03-26 | D4982: CH_01 | E4982: RT_PROMO | F4982: 9346.72 | G4982: 1402.01 | H4982: 7944.71 | I4982: Cancelled
A4983: BK14982 | B4983: 2024-10-11 | C4983: 2024-11-05 | D4983: CH_06 | E4983: RT_CORP | F4983: 6702.82 | G4983: 335.14 | H4983: 6367.68 | I4983: Cancelled
A4984: BK14983 | B4984: 2024-11-16 | C4984: 2024-12-12 | D4984: CH_01 | E4984: RT_NET | F4984: 9958.9 | G4984: 0 | H4984: 9958.9 | I4984: Checked-Out
... A5001: BK15000 | B5001: 2024-03-27 | C5001: 2024-04-23 | D5001: CH_02 | E5001: RT_BAR | F5001: 6607.36 | G5001: 1189.32 | H5001: 5418.04 | I5001: Checked-Out

Sheet dim_channels
A1: channel_id | B1: channel_name | C1: channel_type | D1: commission_model | E1: default_commission_rate | F1: contract_owner
A2: CH_01 | B2: Booking.com | C2: OTA | D2: Percentage | E2: 0.15 | F2: Somchai P.
A3: CH_02 | B3: Expedia | C3: OTA | D3: Percentage | E3: 0.18 | F3: Somchai P.
A4: CH_03 | B4: Agoda | C4: OTA | D4: Percentage | E4: 0.12 | F4: Nattaya K.
A5: CH_04 | B5: Direct Website | C5: Direct | D5: Flat Fee | E5: 0 | F5: Nattaya K.
A6: CH_05 | B6: Walk-in | C6: Direct | D6: Flat Fee | E6: 0 | F6: Nattaya K.
A7: CH_06 | B7: Corporate Direct | C7: Corporate | D7: Flat Fee | E7: 0.05 | F7: Wichai S.
A8: CH_07 | B8: Travel Agency | C8: Offline | D8: Percentage | E8: 0.1 | F8: Wichai S.
A9: CH_08 | B9: GDS (Amadeus) | C9: GDS | D9: Percentage | E9: 0.2 | F9: Somchai P.

Sheet dim_rate_codes
A1: rate_code_id | B1: rate_name | C1: is_commissionable
A2: RT_BAR | B2: Best Available Rate | C2: TRUE
A3: RT_CORP | B3: Corporate Rate | C3: TRUE
A4: RT_PKG | B4: Package Rate | C4: TRUE
A5: RT_NET | B5: Net Rate (OTA) | C5: FALSE
A6: RT_PROMO | B6: Promotional Rate | C6: TRUE
A7: RT_WALK | B7: Walk-in Rate | C7: FALSE
A8: RT_GOVT | B8: Government Rate | C8: FALSE

Sheet Detail1
A1: Details for Sum of Netmargin - channel_type: Corporate
A3: booking_id | B3: booking_date | C3: check_in_date | D3: channel_id | E3: rate_code_id | F3: gross_room_revenue | G3: commission_amount | H3: net_room_revenue | I3: status | J3: net_margin | K3: channel_type
A4: BK14984 | B4: 2024-01-25 | C4: 2024-01-30 | D4: CH_06 | E4: RT_GOVT | F4: 10023.3 | G4: 0 | H4: 10023.3 | I4: Checked-Out | J4: 1 | K4: Corporate
A5: BK14931 | B5: 2024-11-15 | C5: 2024-12-03 | D5: CH_06 | E5: RT_GOVT | F5: 10119.34 | G5: 0 | H5: 10119.34 | I5: Checked-Out | J5: 1 | K5: Corporate
A6: BK14901 | B6: 2024-01-19 | C6: 2024-02-10 | D6: CH_06 | E6: RT_GOVT | F6: 6071.27 | G6: 0 | H6: 6071.27 | I6: Checked-Out | J6: 1 | K6: Corporate
A7: BK14879 | B7: 2024-11-25 | C7: 2024-12-05 | D7: CH_06 | E7: RT_GOVT | F7: 6678.3 | G7: 0 | H7: 6678.3 | I7: Checked-Out | J7: 1 | K7: Corporate
A8: BK14857 | B8: 2024-05-28 | C8: 2024-06-24 | D8: CH_06 | E8: RT_GOVT | F8: 2352.93 | G8: 0 | H8: 2352.93 | I8: Checked-Out | J8: 1 | K8: Corporate
A9: BK14851 | B9: 2024-07-27 | C9: 2024-08-05 | D9: CH_06 | E9: RT_GOVT | F9: 12926.17 | G9: 0 | H9: 12926.17 | I9: Confirmed | J9: 1 | K9: Corporate
A10: BK10018 | B10: 2024-12-25 | C10: 2025-01-23 | D10: CH_06 | E10: RT_GOVT | F10: 6660.28 | G10: 0 | H10: 6660.28 | I10: Checked-Out | J10: 1 | K10: Corporate
A11: BK10021 | B11: 2024-11-23 | C11: 2024-12-15 | D11: CH_06 | E11: RT_GOVT | F11: 4095.96 | G11: 0 | H11: 4095.96 | I11: Checked-Out | J11: 1 | K11: Corporate
A12: BK10022 | B12: 2024-01-29 | C12: 2024-02-05 | D12: CH_06 | E12: RT_GOVT | F12: 3001.73 | G12: 0 | H12: 3001.73 | I12: Checked-Out | J12: 1 | K12: Corporate
A13: BK14785 | B13: 2024-02-25 | C13: 2024-02-27 | D13: CH_06 | E13: RT_GOVT | F13: 2401.76 | G13: 0 | H13: 2401.76 | I13: Checked-Out | J13: 1 | K13: Corporate
A14: BK10028 | B14: 2024-07-04 | C14: 2024-07-11 | D14: CH_06 | E14: RT_GOVT | F14: 6396.65 | G14: 0 | H14: 6396.65 | I14: Checked-Out | J14: 1 | K14: Corporate
A15: BK14756 | B15: 2024-09-09 | C15: 2024-09-16 | D15: CH_06 | E15: RT_GOVT | F15: 2747.37 | G15: 0 | H15: 2747.37 | I15: Checked-Out | J15: 1 | K15: Corporate
... A585: BK14124 | B585: 2024-01-22 | C585: 2024-02-05 | D585: CH_06 | E585: RT_CORP | F585: 2205.1 | G585: 110.26 | H585: 2094.84 | I585: Checked-Out | J585: 1.0526341 | K585: Corporate

Sheet Detail2
A1: Details for Sum of Netmargin - channel_type: Corporate
A3: booking_id | B3: booking_date | C3: check_in_date | D3: channel_id | E3: rate_code_id | F3: gross_room_revenue | G3: commission_amount | H3: net_room_revenue | I3: status | J3: net_margin | K3: channel_type
A4: BK14984 | B4: 2024-01-25 | C4: 2024-01-30 | D4: CH_06 | E4: RT_GOVT | F4: 10023.3 | G4: 0 | H4: 10023.3 | I4: Checked-Out | J4: 1 | K4: Corporate
A5: BK14931 | B5: 2024-11-15 | C5: 2024-12-03 | D5: CH_06 | E5: RT_GOVT | F5: 10119.34 | G5: 0 | H5: 10119.34 | I5: Checked-Out | J5: 1 | K5: Corporate
A6: BK14901 | B6: 2024-01-19 | C6: 2024-02-10 | D6: CH_06 | E6: RT_GOVT | F6: 6071.27 | G6: 0 | H6: 6071.27 | I6: Checked-Out | J6: 1 | K6: Corporate
A7: BK14879 | B7: 2024-11-25 | C7: 2024-12-05 | D7: CH_06 | E7: RT_GOVT | F7: 6678.3 | G7: 0 | H7: 6678.3 | I7: Checked-Out | J7: 1 | K7: Corporate
A8: BK14857 | B8: 2024-05-28 | C8: 2024-06-24 | D8: CH_06 | E8: RT_GOVT | F8: 2352.93 | G8: 0 | H8: 2352.93 | I8: Checked-Out | J8: 1 | K8: Corporate
A9: BK14851 | B9: 2024-07-27 | C9: 2024-08-05 | D9: CH_06 | E9: RT_GOVT | F9: 12926.17 | G9: 0 | H9: 12926.17 | I9: Confirmed | J9: 1 | K9: Corporate
A10: BK10018 | B10: 2024-12-25 | C10: 2025-01-23 | D10: CH_06 | E10: RT_GOVT | F10: 6660.28 | G10: 0 | H10: 6660.28 | I10: Checked-Out | J10: 1 | K10: Corporate
A11: BK10021 | B11: 2024-11-23 | C11: 2024-12-15 | D11: CH_06 | E11: RT_GOVT | F11: 4095.96 | G11: 0 | H11: 4095.96 | I11: Checked-Out | J11: 1 | K11: Corporate
A12: BK10022 | B12: 2024-01-29 | C12: 2024-02-05 | D12: CH_06 | E12: RT_GOVT | F12: 3001.73 | G12: 0 | H12: 3001.73 | I12: Checked-Out | J12: 1 | K12: Corporate
A13: BK14785 | B13: 2024-02-25 | C13: 2024-02-27 | D13: CH_06 | E13: RT_GOVT | F13: 2401.76 | G13: 0 | H13: 2401.76 | I13: Checked-Out | J13: 1 | K13: Corporate
A14: BK10028 | B14: 2024-07-04 | C14: 2024-07-11 | D14: CH_06 | E14: RT_GOVT | F14: 6396.65 | G14: 0 | H14: 6396.65 | I14: Checked-Out | J14: 1 | K14: Corporate
A15: BK14756 | B15: 2024-09-09 | C15: 2024-09-16 | D15: CH_06 | E15: RT_GOVT | F15: 2747.37 | G15: 0 | H15: 2747.37 | I15: Checked-Out | J15: 1 | K15: Corporate
... A585: BK14124 | B585: 2024-01-22 | C585: 2024-02-05 | D585: CH_06 | E585: RT_CORP | F585: 2205.1 | G585: 110.26 | H585: 2094.84 | I585: Checked-Out | J585: 1.0526341 | K585: Corporate

Sheet H1,Q1,Q2
A1: H1. Direct channels มี Net ADR และ Net Margin สูงกว่า OTA channels อย่างมีนัยสำคัญ
A2: จริง สูงกว่า9.43%
A5: Q1.ช่องทางที่มี Net ADR สูงจะมี volume bookings ต่ำหรือสูง
A7: สรุป:ช่องทางที่ Net ADR สูงอย่าง Direct / Walk-in มี Volume ที่ดี (ไม่ต่ำ) | B7: Row Labels | C7: Average of net_room_revenue | D7: Sum of net_room_revenue2 | E7: Sum of gross_room_revenue | F7: Sum of Netmargin
A8: ส่วนช่องทางที่เน้น Volume อย่าง OTA ก็มี Net ADR ที่รับได้ (ไม่ได้ต่ำที่สุด) | B8: Corporate | C8: 7414.6191 | D8: 4315308.3 | E8: 4429213.9 | F8: 0.97428312
A9: ดังนั้น โรงแรมจึงควรรักษาบาลานซ์โดยใช้ OTA เพื่อดึง Volume ควบคู่ไปกับการทำโปรโมชัน | B9: CH_06 | C9: 7414.6191 | D9: 4315308.3 | E9: 4429213.9 | F9: 0.97428312
A10: กระตุ้นให้ลูกค้ามาจอง Direct มากขึ้นเพื่อดึงกำไร (Net ADR) ให้สูงสุด | B10: Direct | C10: 9632.2961 | D10: 9237372 | E10: 9237372 | F10: 1
B11: CH_04 | C11: 9395.3135 | D11: 7112252.3 | E11: 7112252.3 | F11: 1
A12: Q2.OTA vs Direct → ต่างกัน กี่ % ใน Net Margin | B12: CH_05 | C12: 10520.394 | D12: 2125119.7 | E12: 2125119.7 | F12: 1
A13: =GETPIVOTDATA("Sum of Netmargin",$B$7,"channel_type","Direct")-GETPIVOTDATA("Sum of Netmargin",$B$7,"channel_type","OTA") -> 0.094321073 | B13: GDS | C13: 6607.3302 | D13: 2074701.7 | E13: 2593377 | F13: 0.80000001
B14: CH_08 | C14: 6607.3302 | D14: 2074701.7 | E14: 2593377 | F14: 0.80000001
B15: Offline | C15: 7892.7552 | D15: 2754571.6 | E15: 3060635.2 | F15: 0.89999997
B16: CH_07 | C16: 7892.7552 | D16: 2754571.6 | E16: 3060635.2 | F16: 0.89999997
B17: OTA | C17: 7453.9648 | D17: 20841286 | E17: 23011781 | F17: 0.90567893
B18: CH_01 | C18: 7469.1135 | D18: 8365407.1 | E18: 9283169.1 | F18: 0.901137
B19: CH_02 | C19: 7641.583 | D19: 5991001.1 | E19: 6813755.5 | F19: 0.87925097
B20: CH_03 | C20: 7270.0418 | D20: 6484877.3 | E20: 6914857 | F20: 0.937818
B21: Grand Total | C21: 7844.6478 | D21: 39223239 | E21: 42332380 | F21: 0.92655408

Sheet H2,Q3,Q4
A1: H2.ช่องทาง OTA มีอัตราการยกเลิกการจองสูงกว่าส่งผลให้รายได้ที่เกิดขึ้นจริงลดลง และทำให้ประสิทธิภาพด้านต้นทุนลดลง
A2: เป็นจริง | B2: เนื่องจากOTA มีอัตราการยกเลิกสูง ทำให้จำนวนการเข้าพักจริงลดลง ส่งผลให้รายได้ที่ได้จริง (realized revenue)
B3: ต่ำกว่าที่คาด และเมื่อรวมกับค่าคอมมิชชั่นที่สูง ทำให้ประสิทธิภาพด้านต้นทุนแย่ลงและกำไรลดลง
A25: Q3. Cancellation ส่งผลต่อ Net Revenue จริง มากแค่ไหน
A28: OTA สร้าง | B28: ยอดขายสูง แต่มี cancellation สูง ทำให้รายได้จริงลดลงอย่างมีนัยสำคัญ และเกิด lost revenue จำนวนมากในขณะที่
A29: Direct channels แม้ volume น้อยกว่า แต่ให้รายได้ที่ “มั่นคงและคาดการณ์ได้” มากกว่า
A61: Q4.มีความสัมพันธ์ระหว่าง:Commission สูง Net ADR ต่ำ จริงหรือไม่
A62: Channels ที่มี commission สูง จะทำให้ Net ADR และ Net Margin ลดลงอย่างมีนัยสำคัญ
A89: Q5 Cancellation ส่งผลต่อ average net margin ต่อ booking ที่ “สำเร็จจริง” แค่ไหน
A90: แม้ช่องทาง OTA จะมีอัตราการยกเลิกการจองสูงกว่าช่องทางอื่นอย่างมีนัยสำคัญแต่ Cancellation แทบไม่ส่งผลต่อ Average Net Margin ต่อ booking ที่สำเร็จ

Sheet H3,Q6
A1: H3Channels ที่มี Commission สูง จะมี Net Revenue ต่อ booking ต่ำกว่า
A2: โดยรวม Channels ที่มี commission สูง มีแนวโน้มให้ Net Revenue ต่อ booking ต่ำกว่า
A31: Q6ถ้าตัด OTA ออก → รายได้หายไปเท่าไร vs margin ดีขึ้นเท่าไร
A32: พบว่า OTA เป็นแหล่งรายได้หลักของโรงแรม โดยสร้างรายได้มากกว่า 50%แต่มีต้นทุนสูงและ
A33: margin ต่ำกว่าเมื่อจำลองการตัด OTA ออก พบว่ารายได้และจำนวน booking
A34: ลดลงอย่างมีนัยสำคัญแม้ว่า margin จะดีขึ้นดังนั้น OTA มีบทบาทสำคัญในด้านการสร้าง
A35: demandขณะที่ช่องทาง direct มีประสิทธิภาพด้านกำไรที่ดีกว่ากลยุทธ์ที่เหมาะสมคือการ
A36: optimize สัดส่วนช่องทางไม่ใช่การตัด OTA ออกทั้งหมด

Sheet H1_NetADR_NetMargin
A3: Row Labels | B3: Average of net_room_revenue | C3: Sum of net_room_revenue | D3: Sum of gross_room_revenue | F3: Net Margin
A4: CH_01 | B4: 7469.1135 | C4: 8365407.1 | D4: 9283169.1 | F4: =GETPIVOTDATA("Sum of net_room_revenue",$A$3,"channel_id","CH_01")/GETPIVOTDATA("Sum of gross_room_revenue",$A$3,"channel_id","CH_01")*100 -> 90.1137
A5: CH_02 | B5: 7641.583 | C5: 5991001.1 | D5: 6813755.5 | F5: =GETPIVOTDATA("Sum of net_room_revenue",$A$3,"channel_id","CH_02")/GETPIVOTDATA("Sum of gross_room_revenue",$A$3,"channel_id","CH_02")*100 -> 87.925097
A6: CH_03 | B6: 7270.0418 | C6: 6484877.3 | D6: 6914857 | F6: =GETPIVOTDATA("Sum of net_room_revenue",$A$3,"channel_id","CH_03")/GETPIVOTDATA("Sum of gross_room_revenue",$A$3,"channel_id","CH_03")*100 -> 93.7818
A7: CH_04 | B7: 9395.3135 | C7: 7112252.3 | D7: 7112252.3 | F7: =GETPIVOTDATA("Sum of net_room_revenue",$A$3,"channel_id","CH_04")/GETPIVOTDATA("Sum of gross_room_revenue",$A$3,"channel_id","CH_04")*100 -> 100
A8: CH_05 | B8: 10520.394 | C8: 2125119.7 | D8: 2125119.7 | F8: =GETPIVOTDATA("Sum of net_room_revenue",$A$3,"channel_id","CH_05")/GETPIVOTDATA("Sum of gross_room_revenue",$A$3,"channel_id","CH_05")*100 -> 100
A9: CH_06 | B9: 7414.6191 | C9: 4315308.3 | D9: 4429213.9 | F9: =GETPIVOTDATA("Sum of net_room_revenue",$A$3,"channel_id","CH_06")/GETPIVOTDATA("Sum of gross_room_revenue",$A$3,"channel_id","CH_06")*100 -> 97.428312
A10: CH_07 | B10: 7892.7552 | C10: 2754571.6 | D10: 3060635.2 | F10: =GETPIVOTDATA("Sum of net_room_revenue",$A$3,"channel_id","CH_07")/GETPIVOTDATA("Sum of gross_room_revenue",$A$3,"channel_id","CH_07")*100 -> 89.999997
A11: CH_08 | B11: 6607.3302 | C11: 2074701.7 | D11: 2593377 | F11: =GETPIVOTDATA("Sum of net_room_revenue",$A$3,"channel_id","CH_08")/GETPIVOTDATA("Sum of gross_room_revenue",$A$3,"channel_id","CH_08")*100 -> 80.000001
A12: Grand Total | B12: 7844.6478 | C12: 39223239 | D12: 42332380
A17: Q2.OTA vs Direct → ต่างกัน กี่ % ใน Net Margin
A18: =9.43% -> 0.0943
A19: Row Labels | B19: Average of net_room_revenue | C19: Sum of net_room_revenue | D19: Average of gross_room_revenue | E19: Average of Netmargin
A20: Corporate | B20: 7414.6191 | C20: 4315308.3 | D20: 7610.3331 | E20: 0.97428312
A21: CH_06 | B21: 7414.6191 | C21: 4315308.3 | D21: 7610.3331 | E21: 0.97428312
A22: Direct | B22: 9632.2961 | C22: 9237372 | D22: 9632.2961 | E22: 1
A23: CH_04 | B23: 9395.3135 | C23: 7112252.3 | D23: 9395.3135 | E23: 1
A24: CH_05 | B24: 10520.394 | C24: 2125119.7 | D24: 10520.394 | E24: 1
A25: GDS | B25: 6607.3302 | C25: 2074701.7 | D25: 8259.1625 | E25: 0.80000001
A26: CH_08 | B26: 6607.3302 | C26: 2074701.7 | D26: 8259.1625 | E26: 0.80000001
A27: Offline | B27: 7892.7552 | C27: 2754571.6 | D27: 8769.7282 | E27: 0.89999997
A28: CH_07 | B28: 7892.7552 | C28: 2754571.6 | D28: 8769.7282 | E28: 0.89999997
A29: OTA | B29: 7453.9648 | C29: 20841286 | D29: 8230.2509 | E29: 0.90567893
A30: CH_01 | B30: 7469.1135 | C30: 8365407.1 | D30: 8288.5438 | E30: 0.901137
A31: CH_02 | B31: 7641.583 | C31: 5991001.1 | D31: 8691.0146 | E31: 0.87925097
... A33: Grand Total | B33: 7844.6478 | C33: 39223239 | D33: 8466.4759 | E33: 0.92655408
H35: H1. Direct channels มี Net ADR และ Net Margin สูงกว่า OTA channels อย่างมีนัยสำคัญ
A36: Row Labels | B36: Average of net_room_revenue | C36: Sum of net_room_revenue2 | D36: Sum of gross_room_revenue | E36: Sum of Netmargin | H36: จริง สูงกว่า9.43%
A37: Corporate | B37: 7414.6191 | C37: 4315308.3 | D37: 4429213.9 | E37: 0.97428312
A38: CH_06 | B38: 7414.6191 | C38: 4315308.3 | D38: 4429213.9 | E38: 0.97428312
A39: Direct | B39: 9632.2961 | C39: 9237372 | D39: 9237372 | E39: 1
A40: CH_04 | B40: 9395.3135 | C40: 7112252.3 | D40: 7112252.3 | E40: 1
A41: CH_05 | B41: 10520.394 | C41: 2125119.7 | D41: 2125119.7 | E41: 1
A42: GDS | B42: 6607.3302 | C42: 2074701.7 | D42: 2593377 | E42: 0.80000001
A43: CH_08 | B43: 6607.3302 | C43: 2074701.7 | D43: 2593377 | E43: 0.80000001
A44: Offline | B44: 7892.7552 | C44: 2754571.6 | D44: 3060635.2 | E44: 0.89999997
A45: CH_07 | B45: 7892.7552 | C45: 2754571.6 | D45: 3060635.2 | E45: 0.89999997
A46: OTA | B46: 7453.9648 | C46: 20841286 | D46: 23011781 | E46: 0.90567893
A47: CH_01 | B47: 7469.1135 | C47: 8365407.1 | D47: 9283169.1 | E47: 0.901137
A48: CH_02 | B48: 7641.583 | C48: 5991001.1 | D48: 6813755.5 | E48: 0.87925097
...

Sheet H2_ช่องทาง OTA มีอัตราการยกเลิก
B3: Column Labels
B4: Checked-Out | E4: Total Count of booking_id | F4: Total Sum of Net_revenue | G4: Total Sum of Gross Revenue
A5: Row Labels | B5: Count of booking_id | C5: Sum of Net_revenue | D5: Sum of Gross Revenue
A6: Corporate | B6: 439 | C6: 3279589.4 | D6: 3365293 | E6: 439 | F6: 3279589.4 | G6: 3365293
A7: Corporate Direct | B7: 439 | C7: 3279589.4 | D7: 3365293 | E7: 439 | F7: 3279589.4 | G7: 3365293
A8: Direct | B8: 714 | C8: 6859360.9 | D8: 6859360.9 | E8: 714 | F8: 6859360.9 | G8: 6859360.9
A9: Direct Website | B9: 562 | C9: 5260114.6 | D9: 5260114.6 | E9: 562 | F9: 5260114.6 | G9: 5260114.6
A10: Walk-in | B10: 152 | C10: 1599246.2 | D10: 1599246.2 | E10: 152 | F10: 1599246.2 | G10: 1599246.2
A11: GDS | B11: 209 | C11: 1366196.3 | D11: 1707745.3 | E11: 209 | F11: 1366196.3 | G11: 1707745.3
A12: GDS (Amadeus) | B12: 209 | C12: 1366196.3 | D12: 1707745.3 | E12: 209 | F12: 1366196.3 | G12: 1707745.3
A13: Offline | B13: 251 | C13: 1990323.6 | D13: 2211470.8 | E13: 251 | F13: 1990323.6 | G13: 2211470.8
A14: Travel Agency | B14: 251 | C14: 1990323.6 | D14: 2211470.8 | E14: 251 | F14: 1990323.6 | G14: 2211470.8
A15: OTA | B15: 1660 | C15: 12548606 | D15: 13875246 | E15: 1660 | F15: 12548606 | G15: 13875246
A16: Agoda | B16: 557 | C16: 4040107.8 | D16: 4300613.2 | E16: 557 | F16: 4040107.8 | G16: 4300613.2
A17: Booking.com | B17: 642 | C17: 4893987.2 | D17: 5442204.6 | E17: 642 | F17: 4893987.2 | G17: 5442204.6
... A19: Grand Total | B19: 3273 | C19: 26044077 | D19: 28019117 | E19: 3273 | F19: 26044077 | G19: 28019117
H25: H2.ช่องทาง OTA มีอัตราการยกเลิกการจองสูงกว่าส่งผลให้รายได้ที่เกิดขึ้นจริงลดลง และทำให้ประสิทธิภาพด้านต้นทุนลดลง
H26: เป็นจริง | I26: เนื่องจากช่องทางOTA มีห้องที่ cancelled มากถึง26.32% อาจจะทำให้รายได้ของโรงแรมหายไปด้วย
B53: Column Labels
B54: Cancelled | E54: Checked-Out | H54: Confirmed | K54: Total Count of booking_id | L54: Total Sum of Net_revenue | M54: Total Sum of Gross Revenue
A55: Row Labels | B55: Count of booking_id | C55: Sum of Net_revenue | D55: Sum of Gross Revenue | E55: Count of booking_id | F55: Sum of Net_revenue | G55: Sum of Gross Revenue | H55: Count of booking_id | I55: Sum of Net_revenue | J55: Sum of Gross Revenue
A56: Corporate | B56: 0.104811 | C56: 0 | D56: 0 | E56: 0.75429553 | F56: 3279589.4 | G56: 3365293 | H56: 0.14089347 | I56: 0 | J56: 0 | K56: 1 | L56: 3279589.4 | M56: 3365293
A57: Corporate Direct | B57: 0.104811 | C57: 0 | D57: 0 | E57: 0.75429553 | F57: 3279589.4 | G57: 3365293 | H57: 0.14089347 | I57: 0 | J57: 0 | K57: 1 | L57: 3279589.4 | M57: 3365293
A58: Direct | B58: 0.11261731 | C58: 0 | D58: 0 | E58: 0.74452555 | F58: 6859360.9 | G58: 6859360.9 | H58: 0.14285714 | I58: 0 | J58: 0 | K58: 1 | L58: 6859360.9 | M58: 6859360.9
A59: Direct Website | B59: 0.11889036 | C59: 0 | D59: 0 | E59: 0.74240423 | F59: 5260114.6 | G59: 5260114.6 | H59: 0.13870542 | I59: 0 | J59: 0 | K59: 1 | L59: 5260114.6 | M59: 5260114.6
A60: Walk-in | B60: 0.089108911 | C60: 0 | D60: 0 | E60: 0.75247525 | F60: 1599246.2 | G60: 1599246.2 | H60: 0.15841584 | I60: 0 | J60: 0 | K60: 1 | L60: 1599246.2 | M60: 1599246.2
A61: GDS | B61: 0.18152866 | C61: 0 | D61: 0 | E61: 0.6656051 | F61: 1366196.3 | G61: 1707745.4 | H61: 0.15286624 | I61: 0 | J61: 0 | K61: 1 | L61: 1366196.3 | M61: 1707745.4
A62: GDS (Amadeus) | B62: 0.18152866 | C62: 0 | D62: 0 | E62: 0.6656051 | F62: 1366196.3 | G62: 1707745.4 | H62: 0.15286624 | I62: 0 | J62: 0 | K62: 1 | L62: 1366196.3 | M62: 1707745.4
A63: Offline | B63: 0.14899713 | C63: 0 | D63: 0 | E63: 0.71919771 | F63: 1990323.6 | G63: 2211470.8 | H63: 0.13180516 | I63: 0 | J63: 0 | K63: 1 | L63: 1990323.6 | M63: 2211470.8
A64: Travel Agency | B64: 0.14899713 | C64: 0 | D64: 0 | E64: 0.71919771 | F64: 1990323.6 | G64: 2211470.8 | H64: 0.13180516 | I64: 0 | J64: 0 | K64: 1 | L64: 1990323.6 | M64: 2211470.8
A65: OTA | B65: 0.26323319 | C65: 0 | D65: 0 | E65: 0.59370529 | F65: 12548606 | G65: 13875246 | H65: 0.14306152 | I65: 0 | J65: 0 | K65: 1 | L65: 12548606 | M65: 13875246
A66: Agoda | B66: 0.22309417 | C66: 0 | D66: 0 | E66: 0.62443946 | F66: 4040107.8 | G66: 4300613.2 | H66: 0.15246637 | I66: 0 | J66: 0 | K66: 1 | L66: 4040107.8 | M66: 4300613.2
A67: Booking.com | B67: 0.29642857 | C67: 0 | D67: 0 | E67: 0.57321429 | F67: 4893987.2 | G67: 5442204.6 | H67: 0.13035714 | I67: 0 | J67: 0 | K67: 1 | L67: 4893987.2 | M67: 5442204.6
... A69: Grand Total | B69: 0.2028 | C69: 0 | D69: 0 | E69: 0.6546 | F69: 26044077 | G69: 28019117 | H69: 0.1426 | I69: 0 | J69: 0 | K69: 1 | L69: 26044077 | M69: 28019117
B73: Q3. Cancellation ส่งผลต่อ Net Revenue จริง มากแค่ไหน
B74: ส่งผลกระทบอย่างมหาศาลเนื่องจาก cancellation ทั้งหมดรวมกัน 20.28% ทำให้รายได้ที่ควรได้หายไป
G81: Q5 Cancellation ส่งผลต่อ average net margin ต่อ booking ที่ “สำเร็จจริง” แค่ไหน
G82: Cancellationไม่ได้ลดทอนเปอร์เซ็นต์ของ net margin ของยอดที่เข้าพักสำเร็จจริง เนื่องจากยอดยกเลิกส่วนใหญ่เป็นของOTA ที่ มี margin ต่ำทำให้ภาพรวมของยอดสำเร็จจริง
B86: Column Labels
B87: Cancelled | D87: Checked-Out | F87: Confirmed | H87: Total Count of booking_id | I87: Total Average of netmargin
...

Sheet H3 Channels ที่มี Commissionสูง
L2: Q3.Cancellation ส่งผลต่อ Net Revenue จริง มากแค่ไหน
L19: Q6ถ้าตัด OTA ออก → รายได้หายไปเท่าไร vs margin ดีขึ้นเท่าไร
A26: Row Labels | B26: Sum of netmargin | C26: Average of net_room_revenue
A27: Agoda | B27: 0.937818 | C27: 7270.0418
A28: OTA | B28: 0.937818 | C28: 7270.0418
A29: Booking.com | B29: 0.901137 | C29: 7469.1135
A30: OTA | B30: 0.901137 | C30: 7469.1135
A31: Corporate Direct | B31: 0.97428312 | C31: 7414.6191
A32: Corporate | B32: 0.97428312 | C32: 7414.6191
A33: Direct Website | B33: 1 | C33: 9395.3135
A34: Direct | B34: 1 | C34: 9395.3135
A35: Expedia | B35: 0.87925097 | C35: 7641.583
A36: OTA | B36: 0.87925097 | C36: 7641.583
A37: GDS (Amadeus) | B37: 0.80000001 | C37: 6607.3302
A38: GDS | B38: 0.80000001 | C38: 6607.3302
... A43: Grand Total | B43: 0.92655408 | C43: 7844.6478
L46: H3Channels ที่มี Commission สูง จะมี Net Revenue ต่อ booking ต่ำกว่า
L47: เป็นจริง
L50: Q4.มีความสัมพันธ์ระหว่าง:Commission สูง Net ADR ต่ำ จริงหรือไม่
B82: Direct (Website, Walk-in) | C82: กำไรดี + เสถียร ควรลงทุนเพิ่ม ยิงads
B83: Corporate | C83: กำไรดี + predictable ควรทำสัญญากับรัฐบาลมากขึ้นและบริษัทแต่ละที่มากขึ้นโดยเป็นสัญญาระยะยาว
B84: Travel Agent | C84: ไม่เด่น แต่มีประโยชน์บางช่วง ใช้เป็นsup
B85: GDS (เช่น Amadeus) | C85: ควรoptimize commission
B86: OTA (Booking, Expedia, Agoda) | C86: ปรับจำนวนห้องให้booking พอประมาณ

Sheet Sheet4
B1: Column Labels
B2: Cancelled | E2: Total Count of booking_id | F2: Total Sum of Net_revenue | G2: Total Sum of Gross Revenue
A3: Row Labels | B3: Count of booking_id | C3: Sum of Net_revenue | D3: Sum of Gross Revenue
A4: Corporate | B4: 61 | C4: 0 | D4: 0 | E4: 61 | F4: 0 | G4: 0
A5: Corporate Direct | B5: 61 | C5: 0 | D5: 0 | E5: 61 | F5: 0 | G5: 0
A6: Direct | B6: 108 | C6: 0 | D6: 0 | E6: 108 | F6: 0 | G6: 0
A7: Direct Website | B7: 90 | C7: 0 | D7: 0 | E7: 90 | F7: 0 | G7: 0
A8: Walk-in | B8: 18 | C8: 0 | D8: 0 | E8: 18 | F8: 0 | G8: 0
A9: GDS | B9: 57 | C9: 0 | D9: 0 | E9: 57 | F9: 0 | G9: 0
A10: GDS (Amadeus) | B10: 57 | C10: 0 | D10: 0 | E10: 57 | F10: 0 | G10: 0
A11: Offline | B11: 52 | C11: 0 | D11: 0 | E11: 52 | F11: 0 | G11: 0
A12: Travel Agency | B12: 52 | C12: 0 | D12: 0 | E12: 52 | F12: 0 | G12: 0
A13: OTA | B13: 736 | C13: 0 | D13: 0 | E13: 736 | F13: 0 | G13: 0
A14: Agoda | B14: 199 | C14: 0 | D14: 0 | E14: 199 | F14: 0 | G14: 0
A15: Booking.com | B15: 332 | C15: 0 | D15: 0 | E15: 332 | F15: 0 | G15: 0
... A17: Grand Total | B17: 1014 | C17: 0 | D17: 0 | E17: 1014 | F17: 0 | G17: 0

Sheet Sheet6
A1: Row Labels | B1: Average of net_room_revenue | C1: Sum of net_room_revenue | D1: Sum of gross_room_revenue | E1: Sum of Netmargin
A2: Corporate | B2: 7414.6191 | C2: 4315308.3 | D2: 4429213.9 | E2: 0.97428312
A3: CH_06 | B3: 7414.6191 | C3: 4315308.3 | D3: 4429213.9 | E3: 0.97428312
A4: Direct | B4: 9632.2961 | C4: 9237372 | D4: 9237372 | E4: 1
A5: CH_04 | B5: 9395.3135 | C5: 7112252.3 | D5: 7112252.3 | E5: 1
A6: CH_05 | B6: 10520.394 | C6: 2125119.7 | D6: 2125119.7 | E6: 1
A7: GDS | B7: 6607.3302 | C7: 2074701.7 | D7: 2593377 | E7: 0.80000001
A8: CH_08 | B8: 6607.3302 | C8: 2074701.7 | D8: 2593377 | E8: 0.80000001
A9: Offline | B9: 7892.7552 | C9: 2754571.6 | D9: 3060635.2 | E9: 0.89999997
A10: CH_07 | B10: 7892.7552 | C10: 2754571.6 | D10: 3060635.2 | E10: 0.89999997
A11: OTA | B11: 7453.9648 | C11: 20841286 | D11: 23011781 | E11: 0.90567893
A12: CH_01 | B12: 7469.1135 | C12: 8365407.1 | D12: 9283169.1 | E12: 0.901137
A13: CH_02 | B13: 7641.583 | C13: 5991001.1 | D13: 6813755.5 | E13: 0.87925097
... A15: Grand Total | B15: 7844.6478 | C15: 39223239 | D15: 42332380 | E15: 0.92655408
